<?xml version='1.0'?>
<robot name="Allegrohand">
  <link name="base_link">
        <visual>
            <origin xyz="0.0 0.0 0.0" rpy="0 0 0" />
            <geometry>
                <mesh filename="file:///home/lins/MetaGrasp/grippers/meshes/allegro_hand/base_link.obj" scale="1 1 1" />
            </geometry>
        </visual>
    </link>

    <link name="link_0.0">
        <visual>
            <origin xyz="0.0 0.0 0.0" rpy="0 0 0" />
            <geometry>
                <mesh filename="file:///home/lins/MetaGrasp/grippers/meshes/allegro_hand/link_0.0.obj"/>
            </geometry>
        </visual>
    </link>  

    <joint name="joint_0.0" type="revolute">
        <axis xyz="0 0 1"/>
        <limit effort="0" lower="-0.47" upper="0.47" velocity="0"/>
        <parent link="base_link"/>
        <child link="link_0.0"/>
        <origin rpy="-0.08726646255 0 0" xyz="0 0.0436512 -0.0022438"/>
    </joint>

    <link name="link_1.0">
        <visual>
            <origin xyz="0.0 0.0 0.0" rpy="0 0 0" />
            <geometry>
                <mesh filename="file:///home/lins/MetaGrasp/grippers/meshes/allegro_hand/link_1.0.obj"/>
            </geometry>
        </visual>
    </link>

    <joint name="joint_1.0" type="revolute">
        <limit effort="0" lower="-0.196" upper="1.61" velocity="0"/>
        <axis xyz="0 1 0"/>
        <parent link="link_0.0"/>
        <child link="link_1.0"/>
        <origin xyz="0 0 0.0166" rpy="0 0 0"/>
    </joint>
    
    <link name="link_2.0">
        <visual>
            <origin xyz="0.0 0.0 0.0" rpy="0 0 0" />
            <geometry>
                <mesh filename="file:///home/lins/MetaGrasp/grippers/meshes/allegro_hand/link_2.0.obj"/>
            </geometry>
        </visual>
    </link>

    <joint name="joint_2.0" type="revolute">
        <axis xyz="0 1 0"/>
        <limit effort="0" lower="-0.174" upper="1.709" velocity="0"/>
        <parent link="link_1.0"/>
        <child link="link_2.0"/>
        <origin xyz="0 0 0.054" rpy="0 0 0"/>
    </joint>    

    <link name="link_3.0">
        <visual>
             <origin xyz="0.0 0.0 0.0" rpy="0 0 0" />
            <geometry>
                <mesh filename="file:///home/lins/MetaGrasp/grippers/meshes/allegro_hand/link_3.0.obj"/>
            </geometry>
        </visual>
    </link>

    <joint name="joint_3.0" type="revolute">
        <axis xyz="0 1 0"/>
        <limit effort="0" lower="-0.227" upper="1.618" velocity="0"/>
        <parent link="link_2.0"/>
        <child link="link_3.0"/>
        <origin xyz="0 0 0.0384" rpy="0 0 0"/>
    </joint>


    <link name="link_3.0_tip">
        <visual>
            <origin xyz="0.0 0.0 0.0" rpy="0 0 0" />
            <geometry>
              <mesh filename="file:///home/lins/MetaGrasp/grippers/meshes/allegro_hand/link_3.0_tip_new.obj"/>
            </geometry>
        </visual>
    </link>

    <joint name="joint_3.0_tip" type="fixed">
        <parent link="link_3.0"/>
        <child link="link_3.0_tip"/>
        <origin rpy="0 0 0" xyz="0 0 0.0297"/> <!--The tip joint is in the center of the sphere, which is 0.0157+0.014 m from the joint_3.0-->
    </joint> 

    <link name="link_4.0">
        <visual>
             <origin xyz="0.0 0.0 0.0" rpy="0 0 0" />
            <geometry>
                <mesh filename="file:///home/lins/MetaGrasp/grippers/meshes/allegro_hand/link_0.0.obj"/>
            </geometry>
        </visual>
    </link> 

    <joint name="joint_4.0" type="revolute">
        <axis xyz="0 0 1"/>
        <limit effort="0" lower="-0.47" upper="0.47" velocity="0"/>
        <parent link="base_link"/>
        <child link="link_4.0"/>
        <origin xyz="0.0 0.0 0.0" rpy="0.0 0.0 0.0"/>
    </joint>

    <link name="link_5.0">
        <visual>
              <origin xyz="0.0 0.0 0.0" rpy="0 0 0" />
           <geometry>
                <mesh filename="file:///home/lins/MetaGrasp/grippers/meshes/allegro_hand/link_1.0.obj"/>
            </geometry>
        </visual>
    </link>
    
    <joint name="joint_5.0" type="revolute">
        <limit effort="0" lower="-0.196" upper="1.61" velocity="0"/>
        <axis xyz="0 1 0"/>
        <parent link="link_4.0"/>
        <child link="link_5.0"/>
        <origin xyz="0 0 0.0166" rpy="0 0 0"/>
    </joint>
    
    <link name="link_6.0">
    <visual>
              <origin xyz="0.0 0.0 0.0" rpy="0 0 0" />
       <geometry>
            <mesh filename="file:///home/lins/MetaGrasp/grippers/meshes/allegro_hand/link_2.0.obj"/>
        </geometry>
    </visual>
    </link>
    
    <joint name="joint_6.0" type="revolute">
        <axis xyz="0 1 0"/>
        <limit effort="0" lower="-0.174" upper="1.709" velocity="0"/>
        <parent link="link_5.0"/>
        <child link="link_6.0"/>
        <origin xyz="0 0 0.054" rpy="0 0 0"/>
    </joint>


    <link name="link_7.0">
        <visual>
               <origin xyz="0.0 0.0 0.0" rpy="0 0 0" />
          <geometry>
                <mesh filename="file:///home/lins/MetaGrasp/grippers/meshes/allegro_hand/link_3.0.obj"/>
            </geometry>
        </visual>
    </link>

    <joint name="joint_7.0" type="revolute">
        <axis xyz="0 1 0"/>
        <limit effort="0" lower="-0.227" upper="1.618" velocity="0"/>
        <parent link="link_6.0"/>
        <child link="link_7.0"/>
        <origin xyz="0 0 0.0384" rpy="0 0 0"/>
    </joint>


    <link name="link_7.0_tip">
        <visual>
            <origin xyz="0.0 0.0 0.0" rpy="0 0 0" />
            <geometry>
                <mesh filename="file:///home/lins/MetaGrasp/grippers/meshes/allegro_hand/link_3.0_tip_new.obj"/>
            </geometry>
        </visual>
     </link>

    <joint name="joint_7.0_tip" type="fixed">
        <parent link="link_7.0"/>
        <child link="link_7.0_tip"/>
        <origin rpy="0 0 0" xyz="0 0 0.0297"/> <!--The tip joint is in the center of the sphere, which is 0.0157+0.014 m from the joint_3.0-->
    </joint> 

   
    <link name="link_12.0">
        <visual>
              <origin xyz="0.0 0.0 0.0" rpy="0 0 0" />
           <geometry>
                <mesh filename="file:///home/lins/MetaGrasp/grippers/meshes/allegro_hand/link_12.0_right.obj"/>
            </geometry>
        </visual>
    </link>
    
    <joint name="joint_12.0" type="revolute">
        <axis xyz="1 0 0"/>
        <limit effort="0" lower="-1.396" upper="-1.163" velocity="0"/>
        <parent link="base_link"/>
        <child link="link_12.0"/>
        <origin rpy="0 -1.65806278845 -1.5707963259" xyz="-0.0182 0.0193112 -0.046391"/> <!--"-0.0182 0.016958 -0.073288"-->
    </joint>
    
    <link name="link_13.0">
        <visual>
               <origin xyz="0.0 0.0 0.0" rpy="0 0 0" />
          <geometry>
                <mesh filename="file:///home/lins/MetaGrasp/grippers/meshes/allegro_hand/link_13.0.obj"/>
            </geometry>
        </visual>
    </link>
    
    <joint name="joint_13.0" type="revolute">
        <axis xyz="0 0 1"/>
        <limit effort="0" lower="-0.105" upper="1.163" velocity="0"/>
        <parent link="link_12.0"/>
        <child link="link_13.0"/>
        <origin xyz="-0.027 0.005 0.0388" rpy="0 0 0"/>
    </joint>
    
    <link name="link_14.0">
        <visual>
              <origin xyz="0.0 0.0 0.0" rpy="0 0 0" />
           <geometry>
                <mesh filename="file:///home/lins/MetaGrasp/grippers/meshes/allegro_hand/link_14.0.obj"/>
            </geometry>
        </visual>
     </link>
    
    <joint name="joint_14.0" type="revolute">
        <axis xyz="0 1 0"/>
        <limit effort="0" lower="-0.189" upper="1.644" velocity="0"/>
        <parent link="link_13.0"/>
        <child link="link_14.0"/>
        <origin xyz="0 0 0.0166" rpy="0 0 0"/>
    </joint>

    <link name="link_15.0">
        <visual>
              <origin xyz="0.0 0.0 0.0" rpy="0 0 0" />
           <geometry>
                <mesh filename="file:///home/lins/MetaGrasp/grippers/meshes/allegro_hand/link_15.0.obj"/>
            </geometry>
        </visual>
    </link>

    <joint name="joint_15.0" type="revolute">
        <axis xyz="0 1 0"/>
        <limit effort="0" lower="-0.162" upper="1.719" velocity="0"/>
        <parent link="link_14.0"/>
        <child link="link_15.0"/>
        <origin xyz="0 0 0.0514" rpy="0 0 0"/>
    </joint>

    <link name="link_15.0_tip">
        <visual>
            <origin xyz="0.0 0.0 0.0" rpy="0 0 0" />
            <geometry>
                <mesh filename="file:///home/lins/MetaGrasp/grippers/meshes/allegro_hand/link_3.0_tip_new.obj"/>
            </geometry>
        </visual>
    </link>

    <joint name="joint_15.0_tip" type="fixed">
        <parent link="link_15.0"/>
        <child link="link_15.0_tip"/>
        <origin rpy="0 0 0" xyz="0 0 0.0453"/> <!--31.3+14=45.3-->
    </joint>   


</robot>
