<?xml version="1.0" ?>
<!-- =================================================================================== -->
<!-- |    This document was autogenerated by xacro from j2n6s300_standalone.xacro      | -->
<!-- |    EDITING THIS FILE BY HAND IS NOT RECOMMENDED                                 | -->
<!-- =================================================================================== -->
<!-- j2n6s300 refers to jaco v2 6DOF non-spherical 3fingers -->
<robot name="kinova">
  <link name="base_link">
    <visual>
      <geometry>
        <mesh filename="file:///home/lins/MetaGrasp/grippers/meshes/kinova_kg3/hand_3finger.obj"/>
      </geometry>
      <material name="carbon_fiber">
        <color rgba="0.792156862745098 0.819607843137255 0.933333333333333 1"/>
      </material>
    </visual>
  </link>

  <link name="finger_1">
    <visual>
      <geometry>
        <mesh filename="file:///home/lins/MetaGrasp/grippers/meshes/kinova_kg3/finger_proximal.obj"/>
      </geometry>
      <material name="carbon_fiber">
        <color rgba="0.792156862745098 0.819607843137255 0.933333333333333 1"/>
      </material>
    </visual>
  </link>

  <joint name="joint_finger_1" type="revolute">
    <parent link="base_link"/>
    <child link="finger_1"/>
    <axis xyz="0 0 1"/>
    <origin rpy="-1.570796327 .649262481663582 1.35961148639407" xyz="0.00279 0.03126 -0.11467"/>
    <limit effort="2000" lower="0" upper="2" velocity="1"/>
  </joint>

  <link name="finger_tip_1">
    <visual>
      <geometry>
        <mesh filename="file:///home/lins/MetaGrasp/grippers/meshes/kinova_kg3/finger_distal.obj"/>
      </geometry>
      <material name="carbon_fiber">
        <color rgba="0.792156862745098 0.819607843137255 0.933333333333333 1"/>
      </material>
    </visual>
  </link>
  <joint name="joint_finger_tip_1" type="fixed">
    <parent link="finger_1"/>
    <child link="finger_tip_1"/>
    <axis xyz="0 0 1"/>
    <origin rpy="0 0 0" xyz="0.044 -0.003 0"/>
    <limit effort="2000" lower="0" upper="2" velocity="1"/>
  </joint>


  <link name="finger_2">
    <visual>
      <geometry>
        <mesh filename="file:///home/lins/MetaGrasp/grippers/meshes/kinova_kg3/finger_proximal.obj"/>
      </geometry>
      <material name="carbon_fiber">
        <color rgba="0.792156862745098 0.819607843137255 0.933333333333333 1"/>
      </material>
    </visual>
  </link>

  <joint name="joint_finger_2" type="revolute">
    <parent link="base_link"/>
    <child link="finger_2"/>
    <axis xyz="0 0 1"/>
    <origin rpy="-1.570796327 .649262481663582 -1.38614049188413" xyz="0.02226 -0.02707 -0.11482"/>
    <limit effort="2000" lower="0" upper="2" velocity="1"/>
  </joint>

  <link name="finger_tip_2">
    <visual>
      <geometry>
        <mesh filename="file:///home/lins/MetaGrasp/grippers/meshes/kinova_kg3/finger_distal.obj"/>
      </geometry>
      <material name="carbon_fiber">
        <color rgba="0.792156862745098 0.819607843137255 0.933333333333333 1"/>
      </material>
    </visual>
  </link>

  <joint name="joint_finger_tip_2" type="fixed">
    <parent link="finger_2"/>
    <child link="finger_tip_2"/>
    <axis xyz="0 0 1"/>
    <origin rpy="0 0 0" xyz="0.044 -0.003 0"/>
    <limit effort="2000" lower="0" upper="2" velocity="1"/>
  </joint>

  <link name="finger_3">
    <visual>
      <geometry>
        <mesh filename="file:///home/lins/MetaGrasp/grippers/meshes/kinova_kg3/finger_proximal.obj"/>
      </geometry>
      <material name="carbon_fiber">
        <color rgba="0.792156862745098 0.819607843137255 0.933333333333333 1"/>
      </material>
    </visual>
  </link>

  <joint name="joint_finger_3" type="revolute">
    <parent link="base_link"/>
    <child link="finger_3"/>
    <axis xyz="0 0 1"/>
    <origin rpy="-1.570796327 .649262481663582 -1.75545216211587" xyz="-0.02226 -0.02707 -0.11482"/>
    <limit effort="2000" lower="0" upper="2" velocity="1"/>
  </joint>

  <link name="finger_tip_3">
    <visual>
      <geometry>
        <mesh filename="file:///home/lins/MetaGrasp/grippers/meshes/kinova_kg3/finger_distal.obj"/>
      </geometry>
      <material name="carbon_fiber">
        <color rgba="0.792156862745098 0.819607843137255 0.933333333333333 1"/>
      </material>
    </visual>
  </link>
  <joint name="joint_finger_tip_3" type="fixed">
    <parent link="finger_3"/>
    <child link="finger_tip_3"/>
    <axis xyz="0 0 1"/>
    <origin rpy="0 0 0" xyz="0.044 -0.003 0"/>
    <limit effort="2000" lower="0" upper="2" velocity="1"/>
  </joint>
</robot>
