<?xml version="1.0"?>
<robot name="robotiq_3f">
  <link name="base_link">
    <visual>
      <origin rpy="0 0 0" xyz="0 0 0"/>
      <geometry>
        <mesh filename="file:///home/lins/MetaGrasp/grippers/meshes/robotiq_3f/coupling.obj"/>
      </geometry>
    </visual>
  </link>

  <joint name="couling_joint" type="fixed">
    <parent link="base_link"/>
    <child link="palm"/>
    <origin rpy="1.57079632679 1.57079632679 1.57079632679" xyz="0.04 0.07 0.04"/> 
  </joint>

  <link name="finger_1_link_0">
    <visual>
      <origin rpy="0 0 0" xyz="0 0 0"/>
      <geometry>
        <mesh filename="file:///home/lins/MetaGrasp/grippers/meshes/robotiq_3f/link_0.obj"/>
      </geometry>
    </visual>
  </link>

  <link name="finger_1_link_1">
    <visual>
      <origin rpy="0 0 1.5708" xyz="0 0.05717 0"/> 
      <geometry>
        <mesh filename="file:///home/lins/MetaGrasp/grippers/meshes/robotiq_3f/link_1.obj"/>
      </geometry>
    </visual>
  </link>

  <link name="finger_1_link_2">
    <visual>
      <origin rpy="0 0 1.5708" xyz="0 0.03810 0.0075"/>
      <geometry>
        <mesh filename="file:///home/lins/MetaGrasp/grippers/meshes/robotiq_3f/link_2.obj"/>
      </geometry>
    </visual>
  </link>

  <link name="finger_1_link_3">
    <visual>
      <origin rpy="0 0 0" xyz="0 0 0"/>
      <geometry>
        <mesh filename="file:///home/lins/MetaGrasp/grippers/meshes/robotiq_3f/link_3.obj"/>
      </geometry>
    </visual>
  </link> 

  <!-- Link proximal actuating hinge--> 
  <link name="finger_1_link_proximal_actuating_hinge">
    <visual>
      <origin rpy="0 0 0" xyz="0.01429 0 0"/>
      <geometry>
         <box size="0.02858 0.0075 0.002"/>
      </geometry>
    </visual>
  <link>
  
  <!-- Link paraproximal actuating hinge--> 
  <link name="finger_1_link_paraproximal_actuating_hinge">  
    <visual>
      <origin rpy="0 0 0" xyz="0.01143 0 0"/>
      <geometry>
        <box size="0.02286 .0075 0.002"/>
      </geometry>
    </visual> 
  </link>

  <!-- Link proximal actuating bar-->
  <link name="finger_1_link_proximal_actuating_bar">
    <visual>
      <origin rpy="0 0 0" xyz="0.026789 0 0"/>
      <geometry>
        <box size="0.05398 .0075 0.002"/>
      </geometry>
    </visual>
  </link>

  <!-- Link paraproximal bar -->
  <link name="finger_1_link_paraproximal_bar">
    <visual>
      <origin rpy="0 0 0" xyz="0.02885 0 0"/>
      <geometry>
        <box size="0.05770 .0075 .002"/>
      </geometry>
    </visual>
  </link>

  <!-- Link median actuating hinge -->
  <link name="finger_1_link_median_actuating_hinge">
    <visual>
      <origin rpy="0 0 0" xyz="0 0 0"/>
      <geometry>
        <box size=".02 .02 .002"/>
      </geometry>
    </visual>
  </link>

  <link name="finger_1_link_median_bar">
    <visual>
      <origin rpy="0 0 0" xyz="0.01905 0 0"/>
      <geometry>
        <box size="0.0381 .0075 .002"/>
      </geometry>
    </visual>
  </link>

  <link name="finger_1_link_paramedian_hinge">
    <visual>
      <origin rpy="0 0 0" xyz="0 0 0"/>
      <geometry>
        <box size=".02 .02 .002"/>
      </geometry>
    </visual>
  </link>

  <!-- Link median bar underactuated -->
  <link name="finger_1_link_median_bar_underactuated">
    <visual>
      <origin rpy="0 0 0" xyz="0.01905 0 0"/>
      <geometry>
        <box size="0.0381 .0075 .002"/>
      </geometry>
    </visual>
  </link>

  <!-- Link paradistal hinge -->
  <link name="finger_1_link_paradistal_hinge">
    <visual>
      <origin rpy="0 0 0" xyz="0 0 0"/>
      <geometry>
        <box size=".02 .02 .002"/>
      </geometry>
    </visual>
  </link>

  <!-- Joint proximal actuating hinge -->
  <joint name="finger_1_joint_proximal_actuating_hinge" type="revolute">
    <parent link="finger_1_link_0"/>
    <child link="finger_1_link_proximal_actuating_hinge"/>
    <axis xyz="0 0 1"/>
    <origin rpy="0 0 -2.0906" xyz="0 0 0.01"/>
    <limit effort="100" lower="-3.1416" upper="3.1416" velocity="100"/>
  </joint>

  <!-- Joint paraproximal actuating hinge -->
  <joint name="finger_1_joint_paraproximal_actuating_hinge" type="revolute">
    <parent link="finger_1_link_0"/>
    <child link="finger_1_link_paraproximal_actuating_hinge"/>
    <axis xyz="0 0 1"/>
    <origin rpy="0 0 -2.0906" xyz="0 0 -0.01"/>
    <limit effort="100" lower="-3.1416" upper="3.1416" velocity="100"/>
  </joint>

  <!-- Joint proximal actuating bar -->
  <joint name="finger_1_joint_proximal_actuating_bar" type="revolute">
    <parent link="finger_1_link_proximal_actuating_hinge"/>
    <child link="finger_1_link_proximal_actuating_bar"/>
    <axis xyz="0 0 1"/>
    <origin rpy="0 0 1.8616" xyz="0.02858 0 0"/>
    <limit effort="100" lower="-3.1416" upper="3.1416" velocity="100"/>
  </joint>


  <!-- Joint paraproximal bar -->
  <joint name="finger_1_joint_paraproximal_bar" type="revolute">
    <parent link="finger_1_link_paraproximal_actuating_hinge"/>
    <child link="finger_1_link_paraproximal_bar"/>
    <axis xyz="0 0 1"/>
    <origin rpy="0 0 1.57" xyz="0.02286 0 0"/>
    <limit effort="100" lower="-3.1416" upper="3.1416" velocity="100"/>
  </joint>

  <!-- Joint median actuating hinge -->
  <joint name="finger_1_joint_median_actuating_hinge" type="revolute">
    <parent link="finger_1_link_1"/>
    <child link="finger_1_link_median_actuating_hinge"/>
    <axis xyz="0 0 1"/>
    <origin rpy="0 0 -0.37" xyz="0 0.05715 0.01"/>
    <limit effort="100" lower="-3.1416" upper="3.1416" velocity="100"/>
  </joint>

  <!-- Joint paramedian hinge -->
  <joint name="finger_1_joint_paramedian_hinge" type="revolute">
    <parent link="finger_1_link_1"/>
    <child link="finger_1_link_paramedian_hinge"/>
    <axis xyz="0 0 1"/>
    <!-- -0.37 is hand picked, 0.9719 is hand calculated from atan(0.02381/0.01625) -->
    <origin rpy="0 0 0" xyz="0 0.05715 -0.01"/>
    <limit effort="100" lower="-3.1416" upper="3.1416" velocity="100"/>
  </joint>


  <!-- Joint median actuating hinge median bar -->
  <joint name="finger_1_joint_median_actuating_hinge_median_bar" type="revolute">
    <parent link="finger_1_link_median_actuating_hinge"/>
    <child link="finger_1_link_median_bar"/>
    <axis xyz="0 0 1"/>
    <!-- hand calc 90 deg + atan(0.01516/0.01625) -->
    <origin rpy="0 0 2.3215" xyz="0.01625 0.01516 0"/>
    <limit effort="100" lower="-3.1416" upper="3.1416" velocity="100"/>
  </joint>


  <!-- Joint paradistal hinge -->
  <joint name="finger_1_joint_paradistal_hinge" type="revolute">
    <parent link="finger_1_link_2"/>
    <child link="finger_1_link_paradistal_hinge"/>
    <axis xyz="0 0 1"/>
    <origin rpy="0 0 0" xyz="0 0.039 -0.01"/>
    <limit effort="100" lower="-3.1416" upper="3.1416" velocity="100"/>
  </joint>

  <!-- Joint paramedian hinge median bar underactuated -->
  <joint name="finger_1_joint_paramedian_hinge_median_bar_underactuated" type="revolute">
    <parent link="finger_1_link_paramedian_hinge"/>
    <child link="finger_1_link_median_bar_underactuated"/>
    <axis xyz="0 0 1"/>
    <!-- hand calc 90 deg + atan(0.01227/0.00329) -->
    <origin rpy="0 0 1.5708" xyz="0.01227 0.00329 0"/>
    <limit effort="100" lower="-3.1416" upper="3.1416" velocity="100"/>
  </joint>

  <joint name="finger_1_joint_1" type="revolute">
    <origin rpy="0 0 -2.0906" xyz="0 0 0"/>
    <axis xyz="0 0 1"/>
    <parent link="finger_1_link_0"/>
    <child link="finger_1_link_1"/>
    <dynamics damping="1" friction="9"/>
    <limit effort="60" lower="0" upper="1.2217" velocity="-1"/>
  </joint>

  <joint name="finger_1_joint_2" type="revolute">
    <parent link="finger_1_link_1"/>
    <child link="finger_1_link_2"/> 
    <dynamics dampling="1" friction="0"/>
    <axis xyz="0 0 1"/>
    <origin rpy="0 0 0" xyz="0 0.05715 0"/>
    <limit effort="60" lower="0" upper="1.5708" velocity="-1"/>
  </joint>
   
  <joint name="finger_1_joint_3" type="revolute">
    <parent link="finger_1_link_2"/>
    <child link="finger_1_link_3"/>
    <dynamics dampling="1" friction="0"/>
    <axis xyz="0 0 1"/>
    <origin rpy="0 0 2.0906" xyz="0 0.039 0"/> 
    <limit effort="60" lower="-0.6632" upper="1.0471" velocity="-1"/>
  </joint>

  <joint name="finger_1_link_proximal_actuating_bar_median_actuating_hinge_couple" type="revolute">
      <parent>finger_1_link_median_actuating_hinge</parent>
      <child>finger_1_link_proximal_actuating_bar</child>
      <pose>0.05398 0 0 0 0 0</pose>
      <axis>
        <dynamics>
          <damping>0</damping>
          <friction>0</friction>
        </dynamics>
        <xyz>0 0 1</xyz>
        <use_parent_model_frame>false</use_parent_model_frame>
      </axis>
  </joint>

    <joint name="finger_1_link_median_bar_link_3_couple" type="revolute">
      <parent>finger_1_link_3</parent>
      <child>finger_1_link_median_bar</child>
      <pose>0.0381 0 0 0 0 0</pose>
      <axis>
        <dynamics>
          <damping>0</damping>
          <friction>0</friction>
        </dynamics>
        <xyz>0 0 1</xyz>
        <use_parent_model_frame>false</use_parent_model_frame>
      </axis>
    </joint>

    <joint name="finger_1_link_paramedian_bar_paradistal_hinge_couple" type="revolute">
      <parent>finger_1_link_paradistal_hinge</parent>
      <child>finger_1_link_median_bar_underactuated</child>
      <pose>0.0381 0 0 0 0 0</pose>
      <axis>
        <dynamics>
          <damping>0</damping>
          <friction>0</friction>
        </dynamics>
        <xyz>0 0 1</xyz>
        <use_parent_model_frame>false</use_parent_model_frame>
      </axis>
    </joint>

    <joint name="finger_1_link_paradistal_hinge_link_3_couple" type="revolute">
      <parent>finger_1_link_paradistal_hinge</parent>
      <child>finger_1_link_3</child>
      <pose>0.0381 0 0 0 0 0</pose>
      <axis>
        <dynamics>
          <damping>0</damping>
          <friction>0</friction>
        </dynamics>
        <xyz>0 0 1</xyz>
        <use_parent_model_frame>false</use_parent_model_frame>
      </axis>
    </joint>

    <joint name="finger_1_link_paraproximal_bar_paramedian_hinge_couple" type="revolute">
      <parent>finger_1_link_paramedian_hinge</parent>
      <child>finger_1_link_paraproximal_bar</child>
      <pose>0.05770 0 0 0 0 0</pose>
      <axis>
        <dynamics>
          <damping>0</damping>
          <friction>0</friction>
        </dynamics>
        <xyz>0 0 1</xyz>
        <use_parent_model_frame>false</use_parent_model_frame>
      </axis>
    </joint>


  <!-- Link list-->
  <!-- Link 0 -->
  <link name="finger_2_link_0">
    <visual>
      <origin rpy="0 0 0" xyz="0 0 0"/>
      <geometry>
        <mesh filename="file:///home/lins/MetaGrasp/grippers/meshes/robotiq_3f/link_0.obj"/>
      </geometry>
    </visual>
  </link>

  <link name="finger_2_link_1">
    <visual>
      <origin rpy="0 0 1.5708" xyz="0 0.05717 0"/>
      <geometry>
        <mesh filename="file:///home/lins/MetaGrasp/grippers/meshes/robotiq_3f/link_1.obj"/>
      </geometry>
    </visual>
  </link>

  <link name="finger_2_link_2">
    <visual>
      <origin rpy="0 0 1.5708" xyz="0 0.03810 0.0075"/>
      <geometry>
        <mesh filename="file:///home/lins/MetaGrasp/grippers/meshes/robotiq_3f/link_2.obj"/>
      </geometry>
    </visual> 
  </link>

  <link name="finger_2_link_3"> 
    <visual>
      <origin rpy="0 0 0" xyz="0 0 0"/> 
      <geometry>
        <mesh filename="file:///home/lins/MetaGrasp/grippers/meshes/robotiq_3f/link_3.obj"/>
      </geometry>
    </visual>
  </link> 

  <joint name="finger_2_joint_1" type="revolute">
    <origin rpy="0 0 -2.0906" xyz="0 0 0"/>
    <axis xyz="0 0 1"/>
    <parent link="finger_2_link_0"/>
    <child link="finger_2_link_1"/>
    <dynamics damping="1" friction="0"/> 
    <limit effort="60" lower="0" upper="1.5708" velocity="-1"/>
  </joint>

  <joint name="finger_2_joint_2" type="revolute"> 
    <parent link="finger_2_link_1"/>
    <child link="finger_2_link_2"/>
    <dynamics damping="1" friction="0"/>
    <axis xyz="0 0 1"/>
    <origin rpy="0 0 0" xyz="0 0.05715 0"/>
    <limit effort="60" lower="0" upper="1.5708" velocity="-1"/>
  </joint>

  <joint name="finger_2_joint_3" type="revolute">
    <parent link="finger_2_link_2"/>
    <child link="finger_2_link_3"/>
    <dynamics damping="1" friction="0"/>
    <axis xyz="0 0 1"/>
    <origin rpy="0 0 2.0906" xyz="0 0.039 0"/>
    <limit effort="60" lower="-0.6632" upper="1.0471" velocity="-1"/>
  </joint>


  <link name="finger_middle_link_0">
    <visual>
      <origin rpy="0 0 0" xyz="0 0 0"/>
      <geometry>
        <mesh filename="file:///home/lins/MetaGrasp/grippers/meshes/robotiq_3f/link_0.obj"/>
      </geometry>
    </visual>
  </link>

  <link name="finger_middle_link_1"> 
    <visual>
      <origin rpy="0 0 1.5708" xyz="0 0.05717 0"/>
      <geometry>
        <mesh filename="file:///home/lins/MetaGrasp/grippers/meshes/robotiq_3f/link_1.obj"/>
      </geometry>
    </visual>
  </link>

  <link name="finger_middle_link_2">
    <visual>
      <origin rpy="0 0 1.5708" xyz="0 0.03810 0.0075"/>
      <geometry>
        <mesh filename="file:///home/lins/MetaGrasp/grippers/meshes/robotiq_3f/link_2.obj"/>
      </geometry>
    </visual>
  </link>

  <link name="finger_middle_link_3">
    <visual>
      <origin rpy="0 0 0" xyz="0 0 0"/>
      <geometry>
        <mesh filename="file:///home/lins/MetaGrasp/grippers/meshes/robotiq_3f/link_3.obj"/>
      </geometry>
    </visual>
  </link>

  <joint name="finger_middle_joint_1" type="revolute">
    <origin rpy="0 0 -2.0906" xyz="0 0 0"/>
    <axis xyz="0 0 1"/>
    <parent link="finger_middle_link_0"/>
    <child link="finger_middle_link_1"/>
    <dynamics damping="1" friction="0"/>  
    <limit effort="60" lower="0" upper="1.2217" velocity="-1"/>
  </joint>

  <joint name="finger_middle_joint_2" type="revolute">
    <parent link="finger_middle_link_1"/>
    <child link="finger_middle_link_2"/>
    <dynamics damping="1" friction="0"/> 
    <axis xyz="0 0 1"/>
    <origin rpy="0 0 0" xyz="0 0.05715 0"/>
    <limit effort="60" lower="0" upper="1.5708" velocity="-1"/>
  </joint>

  <joint name="finger_middle_joint_3" type="revolute">
    <parent link="finger_middle_link_2"/> 
    <child link="finger_middle_link_3"/>
    <dynamics damping="1" friction="0"/>
    <axis xyz="0 0 1"/>
    <origin rpy="0 0 2.0906" xyz="0 0.039 0"/>
    <limit effort="60" lower="-0.6632" upper="1.0471" velocity="-1"/>
  </joint>

  <!-- link list-->
  <!-- Link palm-->
  <link name="palm">
    <visual>
      <geometry> 
        <mesh filename="file:///home/lins/MetaGrasp/grippers/meshes/robotiq_3f/palm.obj"/>
      </geometry>
    </visual>
  </link>

  <joint name="palm_finger_1_joint" type="revolute">
    <parent link="palm"/>
    <child link="finger_1_link_0"/>
    <dynamics damping="1" frictio="0"/>
    <axis xyz="0 1 0"/>
    <origin rpy="0 3.1416 -1.57" xyz="-0.0455 0.0214 0.036"/>
    <limit effort="60" lower="-0.2967" upper="0.2967" velocity="-1"/>
  </joint>

  <joint name="palm_finger_2_joint" type="revolute">
    <parent link="palm"/>
    <child link="finger_2_link_0"/>
    <axis xyz="0 1 0"/>
    <origin rpy="0 3.1416 -1.57" xyz="-0.0455 0.0214 -0.036"/>
    <limit effort="60" lower="-0.2967" upper="0.2967" velocity="-1"/>
  </joint>

  <joint name="palm_finger_middle_joint" type="revolute">
    <parent link="palm"/>
    <child link="finger_middle_link_0"/>
    <dynamics damping="1" friction="0"/>
    <axis xyz="0 1 0"/>
    <origin rpy="0 0 1.57" xyz="0.0455 0.0214 0"/>
    <limit effort="60" lower="0" upper="0" velocity="-1"/>
  </joint>
</robot>
