<?xml version="1.0"?>
<robot name="robotiq_3f">
  <link name="base_link">
    <visual>
      <geometry>
        <mesh filename="robotiq_2f_85/visual/robotiq_arg2f_85_base_linkvn.obj"/>
      </geometry>
      <material name="Black"/>
    </visual>
  </link>

  <joint name="robotiq_85_left_knuckle_joint" type="revolute">
    <parent link="base_link"/>
    <child link="robotiq_85_left_knuckle_link"/>
    <axis xyz="1 0 0"/>
    <origin rpy="0 0.0 3.1415926" xyz="0 -0.0306011 0.054904"/>
    <limit lower="0" upper="0.81" velocity="100.0"/>
  </joint>

  <joint name="robotiq_85_right_knuckle_joint" type="revolute">
    <parent link="base_link"/>
    <child link="robotiq_85_right_knuckle_link"/>
    <axis xyz="1 0 0"/>
    <origin rpy="0.0 0.0 0" xyz="0 0.0306011 0.054904"/>
    <limit lower="0" upper="0.81" velocity="100.0"/>
  </joint>

  <link name="robotiq_85_left_knuckle_link">
    <visual>
      <geometry>
        <mesh filename="robotiq_2f_85/visual/robotiq_arg2f_85_outer_knucklevn.obj"/>
      </geometry>
    <material name="Black"/>
    </visual>
  </link>

  <link name="robotiq_85_right_knuckle_link">
    <visual>
      <geometry>
        <mesh filename="robotiq_2f_85/visual/robotiq_arg2f_85_outer_knucklevn.obj"/>
      </geometry>
      <material name="Black"/>
    </visual>
  </link>


  <joint name="robotiq_85_left_finger_joint" type="fixed">
    <parent link="robotiq_85_left_knuckle_link"/>
    <child link="robotiq_85_left_finger_link"/>
    <origin rpy="0 0 0" xyz="0 0.0315 -0.0041"/>
    <limit lower="-3.14" upper="3.14" velocity="100.0"/>
  </joint>

  <joint name="robotiq_85_right_finger_joint" type="fixed">
    <parent link="robotiq_85_right_knuckle_link"/>
    <child link="robotiq_85_right_finger_link"/>
    <origin rpy="0 0 0" xyz="0 0.0315 -0.0041"/>
    <limit lower="-3.14" upper="3.14" velocity="100.0"/>
  </joint>

  <link name="robotiq_85_left_finger_link">
    <visual>
      <geometry>
        <mesh filename="robotiq_2f_85/visual/robotiq_arg2f_85_outer_fingervn.obj"/>
      </geometry>
      <material name="Black"/>
    </visual>
  </link>

  <link name="robotiq_85_right_finger_link">
    <visual>
      <geometry>
        <mesh filename="robotiq_2f_85/visual/robotiq_arg2f_85_outer_fingervn.obj"/>
      </geometry>
      <material name="Black"/>
    </visual>
  </link>

  <joint name="robotiq_85_left_inner_knuckle_joint" type="revolute">
    <parent link="base_link"/>
    <child link="robotiq_85_left_inner_knuckle_link"/>
    <axis xyz="1 0 0"/>
    <origin rpy="0 0.0 0" xyz="0 0.0127 0.06142"/>
    <limit lower="0" upper="0.8757" velocity="100.0"/>
  </joint>


  <joint name="robotiq_85_right_inner_knuckle_joint" type="revolute">
    <parent link="base_link"/>
    <child link="robotiq_85_right_inner_knuckle_link"/>
    <axis xyz="1 0 0"/>
    <origin rpy="0 0 3.1415926" xyz="0 -0.0127 0.06142"/>
    <limit lower="0" upper="0.8757" velocity="100.0"/>
  </joint>

  <link name="robotiq_85_left_inner_knuckle_link">
    <visual>
      <geometry>
        <mesh filename="robotiq_2f_85/visual/robotiq_arg2f_85_inner_knucklevn.obj"/>
      </geometry>
      <material name="Black"/>
    </visual>
  </link>

  <link name="robotiq_85_right_inner_knuckle_link">
    <visual>
     <geometry>
        <mesh filename="robotiq_2f_85/visual/robotiq_arg2f_85_inner_knucklevn.obj"/>
      </geometry>
      <material name="Black"/>
    </visual>
  </link>

  <joint name="robotiq_85_left_finger_tip_joint" type="revolute">
    <parent link="robotiq_85_left_finger_link"/>
    <child link="robotiq_85_left_finger_tip_link"/>
    <axis xyz="1 0 0"/>
    <origin rpy="0.0 0.0 0.0" xyz="0 0.0061 0.0471"/>
    <limit lower="0" upper="-0.8" velocity="100.0"/>
  </joint>

  <joint name="robotiq_85_right_finger_tip_joint" type="revolute">
    <parent link="robotiq_85_right_finger_link"/>
    <child link="robotiq_85_right_finger_tip_link"/>
    <axis xyz="1 0 0"/>
    <origin rpy="0.0 0.0 0.0" xyz="0 0.0061 0.0471"/>
    <limit lower="0" upper="-0.8" velocity="100.0"/>
  </joint>

  <link name="robotiq_85_left_finger_tip_link">
    <visual>
      <geometry>
        <mesh filename="robotiq_2f_85/visual/robotiq_arg2f_85_inner_fingervn.obj"/>
      </geometry>
      <material name="Gray"/>
    </visual>
  </link>

  <link name="robotiq_85_right_finger_tip_link">
    <visual>
      <geometry>
        <mesh filename="robotiq_2f_85/visual/robotiq_arg2f_85_inner_fingervn.obj"/>
      </geometry>
    </visual>
  </link>

  <joint name="robotiq_2f_85_left_inner_finger_pad_joint" type="fixed">
      <origin xyz="0 -0.0220203446692936 0.03242" rpy="0 0 0"/>
      <parent link="robotiq_85_left_finger_tip_link" />
      <child link="robotiq_2f_85_left_inner_finger_pad" />
      <axis xyz="0 0 1" />
  </joint>

  <joint name="robotiq_2f_85_right_inner_finger_pad_joint" type="fixed">
      <origin xyz="0 -0.0220203446692936 0.03242" rpy="0 0 0"/>
      <parent link="robotiq_85_right_finger_tip_link" />
      <child link="robotiq_2f_85_right_inner_finger_pad" />
      <axis xyz="0 0 1" />
  </joint>

  <link name="robotiq_2f_85_left_inner_finger_pad">
      <visual>
        <origin xyz="0 0 0" rpy="0 0 0" />
        <geometry>
          <box size="0.022 0.00635 0.0375"/>
        </geometry>
      </visual>
    </link>


    <link name="robotiq_2f_85_right_inner_finger_pad">
      <visual>
        <origin xyz="0 0 0" rpy="0 0 0" />
        <geometry>
          <box size="0.022 0.00635 0.0375"/>
        </geometry>
      </visual>
    </link>
</robot>
