<?xml version="1.0"?>
<robot name="sawyer_2f">
  <link name="base_link">
    <visual>
      <origin rpy="1.5707963 0 0" xyz="0 0 0"/>
      <geometry>
        <mesh filename="file:///home/lins/MetaGrasp/grippers/meshes/sawyer_hand/base.obj"/> 
      </geometry>
    </visual>
  </link> 
  <link name="leftfinger">
    <visual>
      <origin rpy="0 0 0" xyz="0.00 -0.0 0"/>
      <geometry>
        <mesh filename="file:///home/lins/MetaGrasp/grippers/meshes/sawyer_hand/standard_narrow.obj"/>
      </geometry>
    </visual>
  </link>
  <link name="rightfinger">
    <visual>
      <origin rpy="0 0 3.1415926" xyz="0.00 0.0 0"/>
        <geometry>
          <mesh filename="file:///home/lins/MetaGrasp/grippers/meshes/sawyer_hand/standard_narrow.obj"/>
        </geometry>
    </visual>
  </link>
<joint name="finger_joint1" type="prismatic">
  <parent link="base_link"/>
  <child link="leftfinger"/>
  <origin rpy="0 0 0" xyz="0.003 -0.023 0.04552"/>
  <axis xyz="0 1 0"/>
  <limit effort="20" lower="0.0" upper="0.04" velocity="0.2"/>
</joint>
<joint name="finger_joint2" type="prismatic">
  <parent link="base_link"/>
  <child link="rightfinger"/>
  <origin rpy="0 0 -3.1415926" xyz="0.003 0.023 0.04552"/>
  <axis xyz="0 -1 0"/>
  <limit effort="20" lower="0.0" upper="0.04" velocity="0.2"/>
</joint>
</robot>
