<?xml version="1.0"?>
<robot name="schunk_hand">
    <link name="base_link">
      <visual>
        <origin xyz="0 0 -0.0" rpy="0 0 0" />
        <geometry>
          <mesh filename="file:///home/lins/schunk_svh_driver/description/meshes/basev.obj" />
        </geometry>
      </visual>
    </link>

    <link name="d">
      <visual>
        <origin xyz="0 0 -0.0" rpy="0 0 0" />
        <geometry>
          <mesh filename="file:///home/lins/schunk_svh_driver/description/meshes/None.obj" />
        </geometry>
      </visual>
    </link>

    <link name="h">
      <visual>
        <origin xyz="0 0 -0.0" rpy="0 0 0" />
        <geometry>
          <mesh filename="file:///home/lins/schunk_svh_driver/description/meshes/None.obj" />
        </geometry>
      </visual>
    </link>

    <link name="d2">
      <visual>
        <origin xyz="0 0 -0.0" rpy="0 0 0" />
        <geometry>
          <mesh filename="file:///home/lins/schunk_svh_driver/description/meshes/None.obj" />
        </geometry>
      </visual>
    </link>


    <link name="e1">
      <visual>
        <origin rpy="0 0 0" xyz="0 0.01313 0" />
        <geometry>
          <mesh scale="1 1 1" filename="file:///home/lins/schunk_svh_driver/description/meshes/h10v.obj" />
        </geometry>
      </visual>
    </link>


    <link name="e2">
      <visual>
        <origin rpy="0 0 0" xyz="-0.0007 0 -0.01002" />
        <geometry>
          <mesh scale="1 1 1" filename="file:///home/lins/schunk_svh_driver/description/meshes/h11v.obj" />
        </geometry>
      </visual>
    </link>

    <!-- LENGTH NOT FOUND IN DATASHEET! GUESSED!!! -->
    <link name="e3">
      <visual>
        <origin xyz="0 0 -0.0" rpy="0 0 0" />
        <geometry>
          <mesh filename="file:///home/lins/schunk_svh_driver/description/meshes/None.obj" />
        </geometry>
      </visual>
    </link>

    <link name="e">
      <visual>
        <origin xyz="0 0 -0.0" rpy="0 0 0" />
        <geometry>
          <mesh filename="file:///home/lins/schunk_svh_driver/description/meshes/None.obj" />
        </geometry>
      </visual>
    </link>

    <!-- LENGTH NOT FOUND IN DATASHEET! GUESSED, BUT POSITION CALCULATED: E4 = D-G-F!!! -->
    <link name="e4">
      <visual>
        <origin xyz="0 0 -0.0" rpy="0 0 0" />
        <geometry>
          <mesh filename="file:///home/lins/schunk_svh_driver/description/meshes/None.obj" />
        </geometry>
      </visual>
    </link>

    <!-- LENGTH NOT FOUND IN DATASHEET! GUESSED, BUT POSITION CALCULATED: E5 = D-G!!! -->
    <link name="e5">
      <visual>
        <origin xyz="0 0 -0.0" rpy="0 0 0" />
        <geometry>
          <mesh filename="file:///home/lins/schunk_svh_driver/description/meshes/None.obj" />
        </geometry>
      </visual>
    </link>


    <!-- THUMB LINKS -->
    <link name="z">
      <visual>
        <origin xyz="0 0 0.02442" rpy="0 0 0"/>
        <geometry>
          <mesh scale="1 1 1" filename="file:///home/lins/schunk_svh_driver/description/meshes/d10v.obj" />
        </geometry>
      </visual>
    </link>


    <link name="virtual_a">
      <visual>
        <origin xyz="0 0 -0.0" rpy="0 0 0" />
        <geometry>
          <mesh filename="file:///home/lins/schunk_svh_driver/description/meshes/None.obj" />
        </geometry>
      </visual>
    </link>


    <link name="a">
      <visual>
        <geometry>
          <mesh scale="1 1 1" filename="file:///home/lins/schunk_svh_driver/description/meshes/d11v.obj" />
        </geometry>
      </visual>
      <collision>
        <geometry>
          <mesh scale="1 1 1" filename="file:///home/lins/schunk_svh_driver/description/meshes/d11v.obj" />
        </geometry>
      </collision>
    </link>

    <link name="b">
      <visual>
        <geometry>
          <mesh scale="1 1 1" filename="file:///home/lins/schunk_svh_driver/description/meshes/d12v.obj" />
        </geometry>
      </visual>
      <collision>
        <geometry>
          <mesh scale="1 1 1" filename="file:///home/lins/schunk_svh_driver/description/meshes/d12v.obj" />
        </geometry>
      </collision>
    </link>

    <link name="finger_tip_1">
      <visual>
        <geometry>
          <mesh scale="1 1 1" filename="file:///home/lins/schunk_svh_driver/description/meshes/d13v.obj" />
        </geometry>
      </visual>
      <collision>
        <geometry>
          <mesh scale="1 1 1" filename="file:///home/lins/schunk_svh_driver/description/meshes/d13v.obj" />
        </geometry>
      </collision>
    </link>


    <!-- INDEX FINGER LINKS -->
    <link name="virtual_l">
      <visual>
        <origin xyz="0 0 0.01321" />
        <geometry>
          <mesh filename="file:///home/lins/schunk_svh_driver/description/meshes/f10v.obj" />
        </geometry>
      </visual>
    </link>

    <link name="l">
      <visual>
        <geometry>
          <mesh filename="file:///home/lins/schunk_svh_driver/description/meshes/f11v.obj" />
        </geometry>
      </visual>
      <collision>
        <geometry>
          <mesh filename="file:///home/lins/schunk_svh_driver/description/meshes/f11v.obj" />
        </geometry>
      </collision>
    </link>

    <link name="p">
      <visual>
        <geometry>
          <mesh filename="file:///home/lins/schunk_svh_driver/description/meshes/f12v.obj" />
        </geometry>
      </visual>
      <collision>
        <geometry>
          <mesh filename="file:///home/lins/schunk_svh_driver/description/meshes/f12v.obj" />
        </geometry>
      </collision>
    </link>

    <link name="finger_tip_2">
      <visual>
        <geometry>
          <mesh filename="file:///home/lins/schunk_svh_driver/description/meshes/f13v.obj" />
        </geometry>
      </visual>
      <collision>
        <geometry>
          <mesh filename="file:///home/lins/schunk_svh_driver/description/meshes/f13v.obj" />
        </geometry>
      </collision>
    </link>

    <!-- MIDDLE FINGER LINKS -->
    <link name="virtual_k">
      <visual>
        <origin xyz="0 0 0.01321" />
        <geometry>
          <mesh filename="file:///home/lins/schunk_svh_driver/description/meshes/f20v.obj" />
        </geometry>
      </visual>
    </link>

    <link name="k">
      <visual>
        <geometry>
          <mesh filename="file:///home/lins/schunk_svh_driver/description/meshes/f21v.obj" />
        </geometry>
      </visual>
      <collision>
        <geometry>
          <mesh filename="file:///home/lins/schunk_svh_driver/description/meshes/f21v.obj" />
        </geometry>
      </collision>
    </link>

    <link name="o">
      <visual>
        <geometry>
          <mesh filename="file:///home/lins/schunk_svh_driver/description/meshes/f22v.obj" />
        </geometry>
      </visual>
      <collision>
        <geometry>
          <mesh filename="file:///home/lins/schunk_svh_driver/description/meshes/f22v.obj" />
        </geometry>
      </collision>
    </link>

    <link name="s">
      <visual>
        <geometry>
          <mesh filename="file:///home/lins/schunk_svh_driver/description/meshes/f23v.obj" />
        </geometry>
      </visual>
      <collision>
        <geometry>
          <mesh filename="file:///home/lins/schunk_svh_driver/description/meshes/f23v.obj" />
        </geometry>
      </collision>
    </link>


    <!-- RING FINGER LINKS -->
    <link name="virtual_j">
      <visual>
        <origin xyz="0 0 -0.01321" />
        <geometry>
          <mesh filename="file:///home/lins/schunk_svh_driver/description/meshes/f30v.obj" />
        </geometry>
      </visual>
    </link>

    <link name="j">
      <visual>
        <geometry>
          <mesh filename="file:///home/lins/schunk_svh_driver/description/meshes/f31v.obj" />
        </geometry>
      </visual>
      <collision>
        <geometry>
          <mesh filename="file:///home/lins/schunk_svh_driver/description/meshes/f31v.obj" />
        </geometry>
      </collision>
    </link>

    <link name="n">
      <visual>
        <geometry>
          <mesh filename="file:///home/lins/schunk_svh_driver/description/meshes/f32v.obj" />
        </geometry>
      </visual>
      <collision>
        <geometry>
          <mesh filename="file:///home/lins/schunk_svh_driver/description/meshes/f32v.obj" />
        </geometry>
      </collision>
    </link>

    <link name="finger_tip_3">
      <visual>
        <geometry>
          <mesh filename="file:///home/lins/schunk_svh_driver/description/meshes/f33v.obj" />
        </geometry>
      </visual>
      <collision>
        <geometry>
          <mesh filename="file:///home/lins/schunk_svh_driver/description/meshes/f33v.obj" />
        </geometry>
      </collision>
    </link>

    <!-- LITTLE FINGER LINKS -->
    <link name="virtual_i">
      <visual>
        <origin xyz="0 0 -0.01321" />
        <geometry>
          <mesh filename="file:///home/lins/schunk_svh_driver/description/meshes/f40v.obj" />
        </geometry>
      </visual>
    </link>

    <link name="i">
      <visual>
        <geometry>
          <mesh filename="file:///home/lins/schunk_svh_driver/description/meshes/f41v.obj" />
        </geometry>
      </visual>
      <collision>
        <geometry>
          <mesh filename="file:///home/lins/schunk_svh_driver/description/meshes/f41v.obj" />
        </geometry>
      </collision>
    </link>

    <link name="m">
      <visual>
        <geometry>
          <mesh filename="file:///home/lins/schunk_svh_driver/description/meshes/f42v.obj" />
        </geometry>
      </visual>
      <collision>
        <geometry>
          <mesh filename="file:///home/lins/schunk_svh_driver/description/meshes/f42v.obj" />
        </geometry>
      </collision>
    </link>

    <link name="finger_tip_5">
      <visual>
        <geometry>
          <mesh filename="file:///home/lins/schunk_svh_driver/description/meshes/f43v.obj" />
        </geometry>
      </visual>
      <collision>
        <geometry>
          <mesh filename="file:///home/lins/schunk_svh_driver/description/meshes/f43v.obj" />
        </geometry>
      </collision>
    </link>

    <joint name="Thumb_Flexion" type="revolute">
      <parent link="virtual_a" />
      <child link="a" />
      <limit effort="1000.0" lower="-0.1745" upper="-0.1745" velocity="1" />
      <origin xyz="0 0 0" rpy="0 0 -0.9704" />
      <axis xyz="0 0 1" />
    </joint>


    <joint name="Thumb_Helper" type="fixed">
      <parent link="z" />
      <child link="virtual_a" />
      <origin xyz="0 0 0.04596" rpy="0 -1.5707 3.1416" />
    </joint>


    <!-- BASE_LINE JOINTS -->
    <joint name="Thumb_Opposition" type="revolute">
      <parent link="e1" />
      <child link="z" />
      <limit effort="1000.0" lower="0.51" upper="0.5235987" velocity="1" />
      <!--<limit effort="1000.0" lower="-0.34906" upper="0.5235987" velocity="1" />-->
      <origin xyz="-0.01690 0.02626 0" rpy="0 0.2618 1.571" />
      <axis xyz="0 0 -1" />
    </joint>

    <!-- JOINT NOT FOR BASE_LINE. BUT WRITTEN DOWN HERE FOR BETTER UX -->
    <joint name="f1" type="fixed">
      <parent link="e1" />
      <child link="d" />
      <origin xyz="0 0 0" rpy="0 0 0" />
    </joint>

    <joint name="f2" type="fixed">
      <parent link="d" />
      <child link="h" />
      <origin xyz="0 0 0" rpy="0 0 0" />
    </joint>


    <joint name="f3" type="fixed">
      <parent link="h" />
      <child link="d2" />
      <origin xyz="0 0 0" rpy="0 0 0" />
    </joint>

    <joint name="f4" type="fixed">
      <parent link="base_link" />
      <child link="e1" />
      <origin xyz="0 -0.01313 0.025" rpy="0 0 0" />
    </joint>

    <joint name="$j5" type="revolute">
      <parent link="e1" />
      <child link="e2" />
      <limit effort="1000.0" lower="0.0" upper="0.3496" velocity="1" />
      <origin xyz="0.01840 0.006 0.0375" rpy="0 0 0" />
      <axis xyz="0 0 1" />
      <mimic joint="Thumb_Opposition" multiplier="1" offset="0" />
    </joint>

    <joint name="f5" type="fixed">
      <parent link="e2" />
      <child link="e3" />
      <origin xyz="0 -0.0060 0" rpy="0 0 0" />
    </joint>

    <joint name="f6" type="fixed">
      <parent link="e3" />
      <child link="e" />
      <origin xyz="0 0 0" rpy="0 0 0" />
    </joint>

    <joint name="f7" type="fixed">
      <parent link="e" />
      <child link="e4" />
      <origin xyz="0 0 0" rpy="0 0 0" />
    </joint>

    <joint name="f8" type="fixed">
      <parent link="e" />
      <child link="e5" />
      <origin xyz="0 0 0" rpy="0 0 0" />
    </joint>



    <!-- THUMB JOINTS -->
    <joint name="j3" type="revolute">
      <parent link="a" />
      <child link="b" />
      <limit effort="1000.0" lower="0.52" upper="1.46" velocity="1" />
      <origin xyz="0.0485 0 0" rpy="0 0 0" />
      <axis xyz="0 0 1" />
      <mimic joint="Thumb_Flexion" multiplier="1.01511" offset="0" />
    </joint>

    <joint name="j4" type="revolute">
      <parent link="b" />
      <child link="finger_tip_1" />
      <limit effort="1000.0" lower="0.43" upper="1.73" velocity="1" />
      <origin xyz="0.030 0 0" rpy="0 0 0" />
      <axis xyz="0 0 1" />
      <mimic joint="Thumb_Flexion" multiplier="1.44889" offset="0" />
    </joint>

    <!-- INDEX FINGER JOINTS -->
    <joint name="Index_Finger_Distal" type="revolute">
      <parent link="l" />
      <child link="p" />
      <limit effort="1000.0" lower="0.34" upper="1.64992" velocity="1" />
      <origin xyz="0.04804 0 0" rpy="0 0 0" />
      <axis xyz="0 0 1" />
    </joint>

    <joint name="Index_Finger_Proximal" type="revolute">
      <parent link="virtual_l" />
      <child link="l" />
      <limit effort="1000.0" lower="0.175" upper="0.9249" velocity="1" />
      <origin xyz="0 0 0" rpy="-1.5707 0 0" />
      <axis xyz="0 0 1" />
    </joint>

    <!-- JOINT Finger_Spread in BASE_LINE section for better UX -->
    <joint name="j14" type="revolute">
      <parent link="p" />
      <child link="finger_tip_2" />
      <limit effort="1000.0" lower="0.0" upper="1.394" velocity="1" />
      <origin xyz="0.026 0 0" rpy="0 0 0" />
      <axis xyz="0 0 1" />
      <mimic joint="Index_Finger_Distal" multiplier="1.0450" offset="0" />
    </joint>

    <!-- MIDDLE FINGER JOINTS -->
    <joint name="Middle_Finger_Proximal" type="revolute">
      <parent link="virtual_k" />
      <child link="k" />
      <limit effort="1000.0" lower="0.0" upper="0.79849" velocity="1" />
      <origin xyz="0 0 0" rpy="-1.5707 0 0" />
      <axis xyz="0 0 1" />
    </joint>

    <joint name="Middle_Finger_Distal" type="revolute">
      <parent link="k" />
      <child link="o" />
      <limit effort="1000.0" lower="0" upper="1.334" velocity="1" />
      <origin xyz="0.05004 0 0" rpy="0 0 0" />
      <axis xyz="0 0 1" />
    </joint>

    <joint name="j15" type="revolute">
      <parent link="o" />
      <child link="s" />
      <limit effort="1000.0" lower="0" upper="1.334" velocity="1" />
      <origin xyz="0.032 0 0" rpy="0 0 0" />
      <axis xyz="0 0 1" />
      <mimic joint="Middle_Finger_Distal" multiplier="1.0454" offset="0" />
    </joint>


    <!-- RING FINGER JOINTS -->
    <joint name="Ring_Finger" type="revolute">
      <parent link="virtual_j" />
      <child link="j" />
      <limit effort="1000.0" lower="0.26" upper="1.2440" velocity="1" />
      <origin xyz="0 0 0" rpy="1.5707 0 0" />
      <axis xyz="0 0 1" />
    </joint>

    <joint name="j12" type="revolute">
      <parent link="j" />
      <child link="n" />
      <limit effort="1000.0" lower="0.43" upper="1.761" velocity="1" />
      <origin xyz="0.05004 0 0" rpy="0 0 0" />
      <axis xyz="0 0 1" />
      <mimic joint="Ring_Finger" multiplier="1.3588" offset="0" />
    </joint>

    <joint name="j16" type="revolute">
      <parent link="n" />
      <child link="finger_tip_3" />
      <limit effort="1000.0" lower="0.0" upper="1.39" velocity="1" />
      <origin xyz="0.032 0 0" rpy="0 0 0" />
      <axis xyz="0 0 1" />
      <mimic joint="Ring_Finger" multiplier="1.42093" offset="0" />
    </joint>


    <!-- PINKY JOINTS -->
    <joint name="Pinky" type="revolute">
      <parent link="virtual_i" />
      <child link="i" />
      <limit effort="1000.0" lower="0.0" upper="0.98175" velocity="1" />
      <origin xyz="0 0 0" rpy="1.5707 0 0" />
      <axis xyz="0 0 1" />
    </joint>

    <joint name="j13" type="revolute">
      <parent link="i" />
      <child link="m" />
      <limit effort="1000.0" lower="0" upper="1.334" velocity="1" />
      <origin xyz="0.04454 0 0" rpy="0 0 0" />
      <axis xyz="0 0 1" />
      <mimic joint="Pinky" multiplier="1.35880" offset="0" />
    </joint>

    <joint name="j17" type="revolute">
      <parent link="m" />
      <child link="finger_tip_5" />
      <limit effort="1000.0" lower="0" upper="1.3971" velocity="1" />
      <origin xyz="0.022 0 0" rpy="0 0 0" />
      <axis xyz="0 0 1" />
      <mimic joint="Pinky" multiplier="1.42307" offset="0" />
    </joint>


    <joint name="index_spread" type="revolute">
      <parent link="d2" />
      <child link="virtual_l" />
      <limit effort="1000.0" lower="0.0" upper="0.58" velocity="1" />
      <origin xyz="-0.025 0 0.110" rpy="0 -1.5707 1.5707" />
      <axis xyz="0 0 1" />
      <mimic joint="Finger_Spread" multiplier="0.5" offset="0" />
    </joint>

    <joint name="middle_spread_dummy" type="fixed">
      <parent link="d" />
      <child link="virtual_k" />
      <origin xyz="0 0 0.110" rpy="0 -1.5707 1.5707" />
    </joint>


    <joint name="ring_spread" type="revolute">
      <parent link="e5" />
      <child link="virtual_j" />
      <limit effort="1000.0" lower="0.0" upper="0.58" velocity="1" />
      <origin xyz="0.003855 0 0.0655" rpy="-1.5707 -1.5707 0" />
      <axis xyz="0 0 1" />
      <mimic joint="Finger_Spread" multiplier="0.5" offset="0" />
    </joint>

    <joint name="Finger_Spread" type="revolute">
      <parent link="e4" />
      <child link="virtual_i" />
      <limit effort="1000.0" lower="0.0" upper="0.5829" velocity="1" />
      <origin xyz="0.025355 0 0.056" rpy="-1.5707 -1.5707 0" />
      <axis xyz="0 0 1" />
    </joint>

</robot>
